Workbook
Name Akun: [1]SAA!$D$10:$D$46
Name Akun: [1]SAA!$D$10:$D$46
Name Akun: [1]SAA!$D$10:$D$46
Name Akun: [2]SAA!$D$10:$D$46
Name Akun: [1]SAA!$D$10:$D$46
Name Akun: [1]SAA!$D$10:$D$46
Name Akun: [3]SAA!$D$10:$D$46
Name ANGGOTA: #REF!
Name ANGGOTA: #REF!
Name ANGGOTA: #REF!
Name ANGGOTA: #REF!
Name ANGGOTA: '[4]DATA-ANGGOTA'!$D$15:$D$314
Name ANGGOTA: #REF!
Name ANGGOTA: #REF!
Name Bagan: [5]PERKIRAAN!$B$11:$G$121
Name Bagan: [6]PERKIRAAN!$B$11:$G$121
Name Bahan_Makanan: #REF!
Name Bahan_Makanan: #REF!
Name Bahan_Makanan: #REF!
Name cccc: #REF!
Name cccc: #REF!
Name cccc: #REF!
Name cccc: #REF!
Name cccc: #REF!
Name cccc: #REF!
Name cccc: #REF!
Name cccc: #REF!
Name cccc: #REF!
Name cccc: #REF!
Name cccc: #REF!
Name cccc: #REF!
Name Daftar: [1]SAA!$J$10:$J$46
Name Daftar: [1]SAA!$J$10:$J$46
Name Daftar: [1]SAA!$J$10:$J$46
Name Daftar: [2]SAA!$J$10:$J$46
Name Daftar: [1]SAA!$J$10:$J$46
Name Daftar: [1]SAA!$J$10:$J$46
Name Daftar: [3]SAA!$J$10:$J$46
Name Daftar_Rekanan: #REF!
Name Daftar_Rekanan: #REF!
Name Daftar_Rekanan: #REF!
Name Daftar_Rekanan: #REF!
Name Daftar_Rekanan: #REF!
Name Daftar_Rekanan: #REF!
Name Data_Masuk: Masuk!$B$8:$F$812
Name Input: #REF!
Name Input: #REF!
Name Input: #REF!
Name Input: #REF!
Name Input: #REF!
Name Input: #REF!
Name Input: #REF!
Name Input: #REF!
Name Input: #REF!
Name Input: #REF!
Name Input: #REF!
Name Input: #REF!
Name Jenis_Pembayaran: #REF!
Name Jenis_Pembayaran: #REF!
Name Jenis_Pembayaran: #REF!

Sheet Menu
C4: =IF(Setup!C6="","",Setup!C6) -> Input Nama SPPG di sini
K5: versi04@2025
T7: newest
T8: 13/03/26
F9: BUKU KAS UMUM (BKU) | J9: =NOW() -> 46202.88
F11: BP - KAS DI BANK | H11: LP DANA/ANGGARAN | J11: REFERENSI BARANG
D13: SETUP USER | F13: BP - PETTY CASH | H13: SP TANGGUNG JAWAB | J13: SALDO AWAL BARANG
D15: SALDO AWAL BUKU | F15: BP - BAHAN BAKU | H15: BAP SISA DANA | J15: PENERIMAAN BARANG
D17: ANGGARAN | F17: BP - OPERASIONAL | H17: DAFTAR NOMINATIF | J17: PENGELUARAN BARANG
D19: TRANSAKSI | F19: BP - INSENTIF FASILITAS | H19: CATATAN PENGELUARAN | J19: LAPORAN STOCK BARANG

Sheet Sheet7

Sheet Setup
B3: SETUP USER
B5: ITEM | C5: URAIAN
B6: Nama SPPG | C6: Input Nama SPPG di sini
B7: ID SPPG | Z7: Nama Bln | AA7: Nama Akun | AC7: Nama Sheet | AD7: Password
B8: Alamat | Z8: Januari | AA8: ='Saldo Buku'!C10 -> Petty Cash | AC8: Menu | AD8: menu
B9: Nama Kepala SPPG | Z9: Februari | AA9: ='Saldo Buku'!C11 -> Kas di Bank | AC9: Setup | AD9: setup
B10: Nama Akuntan SPPG | Z10: Maret | AA10: ='Saldo Buku'!C13 -> Dana Bantuan Pemerintah | AC10: Saldo Buku | AD10: saldo
B11: Nama Yayasan | Z11: April | AA11: ='Saldo Buku'!C19 -> Biaya Bahan Baku | AC11: Transaksi | AD11: transaksi
B12: Ketua Yayasan/yang mewakili | Z12: Mei | AA12: ='Saldo Buku'!C20 -> Biaya Operasional | AC12: BKU | AD12: bku
B13: Nomor Rekening/VA | Z13: Juni | AA13: ='Saldo Buku'!C21 -> Biaya Insentif Fasilitas | AC13: BP Kas di Bank | AD13: bank
B14: Tahun Anggaran | Z14: Juli | AC14: BP Petty Cash | AD14: petty
B15: Tgl awal periode ini (dd-mm-yyyy; format text) | C15: 05-01-2026 | D15: contoh: '05-01-2026 | Z15: Agustus | AC15: Bahan Baku | AD15: bahan
B16: Tgl akhir periode ini (dd-mm-yyyy; format text) | C16: 17-01-2026 | D16: contoh: '17-01-2026 | Z16: September | AC16: Operasional | AD16: operasional
B17: Awal periode berikutnya (format text) | D17: contoh: '19 Januari 2026 | Z17: Oktober | AC17: Fasilitas | AD17: fasilitas
B18: Tanggal Pelaporan (format text) | D18: contoh: '17 Januari 2026 | Z18: November | AC18: LPA | AD18: lpa
B19: Tempat Pelaporan | Z19: Desember | AC19: SPTJ | AD19: sptj
B20: Nomor LPA | AC20: BAPSD | AD20: bapsd
B21: Nomor BAPSD | AC21: Referensi Brg | AD21: referensi
AC22: Saldo Brg | AD22: brg
AC23: Masuk | AD23: masuk
AC24: Keluar | AD24: keluar
AC25: Stock Brg Detil | AD25: stockd
AC26: Stock Brg Rekap | AD26: stockr

Sheet Saldo Buku
B1: SALDO AWAL BUKU
B3: Nama SPPG | C3: =": "&Setup!C6 -> : Input Nama SPPG di sini
B4: ID SPPG | C4: =": "&Setup!C7 -> :
B5: Alamat | C5: =": "&Setup!C8 -> :
B7: KODE | C7: NAMA AKUN | D7: SALDO AWAL | E7: SALDO AKHIR | F7: CEK SALDO | G7: Saldo Awal | H7: Saldo Akhir
B8: 1000 | C8: BUKU KAS UMUM | D8: 0 | E8: =BKU!I11 -> 0 | F8: BKU | G8: =D8 -> 0 | H8: =E8 -> 0
B9: 1100 | C9: BUKU PEMBANTU KAS | F9: BP Kas | G9: =D10+D11 -> 0 | H9: =E10+E11 -> 0
B10: 1101 | C10: Petty Cash | D10: 0 | E10: =LR!J27 -> 0 | F10: BP Banper | G10: =SUM(D13:D20) -> 0 | H10: =SUM(E13:E20) -> 0
B11: 1102 | C11: Kas di Bank | D11: 0 | E11: =LR!J28 -> 0 | G11: =IF(G8-G9=0,"Oke, Cocok","Tidak Cocok") -> Oke, Cocok | H11: =IF(H8-H9=0,"Oke, Cocok","Tidak Cocok") -> Oke, Cocok
B12: 2000 | C12: BUKU PEMBANTU JENIS DANA | G12: =IF(G8-G10=0,"Oke, Cocok","Tidak Cocok") -> Oke, Cocok | H12: =IF(H8-H10=0,"Oke, Cocok","Tidak Cocok") -> Oke, Cocok
B13: 2110 | C13: Dana Bantuan Pemerintah | D13: 0 | E13: =LR!K28 -> 0 | F13: INGAT: isi angka hanya di sel warna kuning
B14: 2120 | C14: Pungutan/Setoran PPN | D14: 0 | E14: 0
B15: 2130 | C15: Pungutan/Setoran PPh 21 | D15: 0 | E15: 0
B16: 2140 | C16: Pungutan/Setoran PPh 22 | D16: 0 | E16: 0
B17: 2150 | C17: Pungutan/Setoran PPh 23 | D17: 0 | E17: 0
B18: 2160 | C18: Pungutan/Setoran PPh pasal 4 ayat (2) | D18: 0 | E18: 0
B19: 2120 | C19: Biaya Bahan Baku | D19: 0 | E19: 0
B20: 2130 | C20: Biaya Operasional | D20: 0 | E20: 0
B21: 2140 | C21: Biaya Insentif Fasilitas | D21: 0 | E21: 0
B22: 2122 | C22: Biaya Lainnya | D22: 0 | E22: =[7]LR!J23 -> 0
F26: Saldo BKU = petty cash/cash in hand + Kas di Bank
F27: Saldo BKU = Saldo Bantuan Pemerintah

Sheet Anggaran
C2: 1. ANGGARAN BAHAN MAKANAN | X2: 2. ANGGARAN OPERASIONAL | AF2: 3. ANGGARAN INSENTIF FASILITAS
C3: Hari/Tanggal | D3: Jumlah Paket MBG | E3: Balita | F3: PAUD/ TK/RA | G3: SD/MI 1-3 | H3: SD/MI 4-6 | I3: SMP/ MTs | J3: SMA/ MA/ SMK | K3: SLB | L3: Santri | M3: Pend/ TK | N3: Bumil | O3: Busui | P3: Lain nya | Q3: Harga Satuan Paket MBG | R3: Harga Satuan Paket MBG2 | S3: Rencana Anggaran Biaya (RAB) | T3: Aktual | U3: Selisih | V3: Keterangan | X3: Hari/Tanggal | Y3: Jumlah Paket MBG | Z3: Harga Satuan Paket MBG | AA3: Rencana Anggaran Biaya (RAB) | AB3: Aktual | AC3: Selisih | AD3: Keterangan | AF3: Hari/Tanggal | AG3: Jumlah Paket MBG | AH3: Harga Satuan Paket MBG | AI3: Rencana Anggaran Biaya (RAB) | AJ3: Aktual | AK3: Selisih | AL3: Keterangan
C4: =Setup!C15 -> 05-01-2026 | D4: =SUM(Anggaran_BM[[#This Row],[Balita]:[Santri]]) -> 0 | Q4: 8000 | R4: 10000 | S4: =(Anggaran_BM[[#This Row],[Balita]]+Anggaran_BM[[#This Row],[PAUD/ TK/RA]]+Anggaran_BM[[#This Row],[SD/MI 1-3]])*Anggaran_BM[[#This Row],[Harga Satuan Paket MBG]]+(Anggaran_BM[[#This Row],[SD/MI 4-6]]+Anggaran_BM[[#This Row],[SMP/ MTs]]+Anggaran_BM[[#This Row],[SMA/ MA/ SMK]]+Anggaran_BM[[#This Row],[SLB]]+Anggaran_BM[[#This Row],[Santri]]+Anggaran_BM[[#This Row],[Pend/ TK]]+Anggaran_BM[[#This Row],[Bumil]]+Anggaran_BM[[#This Row],[Busui]]+Anggaran_BM[[#This Row],[Lain nya]])*Anggaran_BM[[#This Row],[Harga Satuan Paket MBG2]] -> 0 | U4: =Anggaran_BM[[#This Row],[Rencana Anggaran Biaya (RAB)]]-Anggaran_BM[[#This Row],[Aktual]] -> 0 | X4: =Anggaran_BM[[#This Row],[Hari/Tanggal]] -> 05-01-2026 | AA4: 0 | AC4: =Anggaran_Ops[[#This Row],[Rencana Anggaran Biaya (RAB)]]-Anggaran_Ops[[#This Row],[Aktual]] -> 0 | AF4: =Anggaran_BM[[#This Row],[Hari/Tanggal]] -> 05-01-2026 | AG4: 3000 | AH4: 2000 | AI4: =Anggaran_SM[[#This Row],[Jumlah Paket MBG]]*Anggaran_SM[[#This Row],[Harga Satuan Paket MBG]] -> 6000000 | AK4: =Anggaran_SM[[#This Row],[Rencana Anggaran Biaya (RAB)]]-Anggaran_SM[[#This Row],[Aktual]] -> 6000000
C5: =C4+1 -> 46028 | D5: =SUM(Anggaran_BM[[#This Row],[Balita]:[Santri]]) -> 0 | Q5: 8000 | R5: 10000 | S5: =(Anggaran_BM[[#This Row],[Balita]]+Anggaran_BM[[#This Row],[PAUD/ TK/RA]]+Anggaran_BM[[#This Row],[SD/MI 1-3]])*Anggaran_BM[[#This Row],[Harga Satuan Paket MBG]]+(Anggaran_BM[[#This Row],[SD/MI 4-6]]+Anggaran_BM[[#This Row],[SMP/ MTs]]+Anggaran_BM[[#This Row],[SMA/ MA/ SMK]]+Anggaran_BM[[#This Row],[SLB]]+Anggaran_BM[[#This Row],[Santri]]+Anggaran_BM[[#This Row],[Pend/ TK]]+Anggaran_BM[[#This Row],[Bumil]]+Anggaran_BM[[#This Row],[Busui]]+Anggaran_BM[[#This Row],[Lain nya]])*Anggaran_BM[[#This Row],[Harga Satuan Paket MBG2]] -> 0 | U5: =Anggaran_BM[[#This Row],[Rencana Anggaran Biaya (RAB)]]-Anggaran_BM[[#This Row],[Aktual]] -> 0 | X5: =Anggaran_BM[[#This Row],[Hari/Tanggal]] -> 46028 | AA5: 0 | AC5: =Anggaran_Ops[[#This Row],[Rencana Anggaran Biaya (RAB)]]-Anggaran_Ops[[#This Row],[Aktual]] -> 0 | AF5: =Anggaran_BM[[#This Row],[Hari/Tanggal]] -> 46028 | AG5: 3000 | AH5: 2000 | AI5: =Anggaran_SM[[#This Row],[Jumlah Paket MBG]]*Anggaran_SM[[#This Row],[Harga Satuan Paket MBG]] -> 6000000 | AK5: =Anggaran_SM[[#This Row],[Rencana Anggaran Biaya (RAB)]]-Anggaran_SM[[#This Row],[Aktual]] -> 6000000
C6: =C5+1 -> 46029 | D6: =SUM(Anggaran_BM[[#This Row],[Balita]:[Santri]]) -> 0 | Q6: 8000 | R6: 10000 | S6: =(Anggaran_BM[[#This Row],[Balita]]+Anggaran_BM[[#This Row],[PAUD/ TK/RA]]+Anggaran_BM[[#This Row],[SD/MI 1-3]])*Anggaran_BM[[#This Row],[Harga Satuan Paket MBG]]+(Anggaran_BM[[#This Row],[SD/MI 4-6]]+Anggaran_BM[[#This Row],[SMP/ MTs]]+Anggaran_BM[[#This Row],[SMA/ MA/ SMK]]+Anggaran_BM[[#This Row],[SLB]]+Anggaran_BM[[#This Row],[Santri]]+Anggaran_BM[[#This Row],[Pend/ TK]]+Anggaran_BM[[#This Row],[Bumil]]+Anggaran_BM[[#This Row],[Busui]]+Anggaran_BM[[#This Row],[Lain nya]])*Anggaran_BM[[#This Row],[Harga Satuan Paket MBG2]] -> 0 | U6: =Anggaran_BM[[#This Row],[Rencana Anggaran Biaya (RAB)]]-Anggaran_BM[[#This Row],[Aktual]] -> 0 | X6: =Anggaran_BM[[#This Row],[Hari/Tanggal]] -> 46029 | AA6: 0 | AC6: =Anggaran_Ops[[#This Row],[Rencana Anggaran Biaya (RAB)]]-Anggaran_Ops[[#This Row],[Aktual]] -> 0 | AF6: =Anggaran_BM[[#This Row],[Hari/Tanggal]] -> 46029 | AG6: 3000 | AH6: 2000 | AI6: =Anggaran_SM[[#This Row],[Jumlah Paket MBG]]*Anggaran_SM[[#This Row],[Harga Satuan Paket MBG]] -> 6000000 | AK6: =Anggaran_SM[[#This Row],[Rencana Anggaran Biaya (RAB)]]-Anggaran_SM[[#This Row],[Aktual]] -> 6000000
C7: =C6+1 -> 46030 | D7: =SUM(Anggaran_BM[[#This Row],[Balita]:[Santri]]) -> 0 | Q7: 8000 | R7: 10000 | S7: =(Anggaran_BM[[#This Row],[Balita]]+Anggaran_BM[[#This Row],[PAUD/ TK/RA]]+Anggaran_BM[[#This Row],[SD/MI 1-3]])*Anggaran_BM[[#This Row],[Harga Satuan Paket MBG]]+(Anggaran_BM[[#This Row],[SD/MI 4-6]]+Anggaran_BM[[#This Row],[SMP/ MTs]]+Anggaran_BM[[#This Row],[SMA/ MA/ SMK]]+Anggaran_BM[[#This Row],[SLB]]+Anggaran_BM[[#This Row],[Santri]]+Anggaran_BM[[#This Row],[Pend/ TK]]+Anggaran_BM[[#This Row],[Bumil]]+Anggaran_BM[[#This Row],[Busui]]+Anggaran_BM[[#This Row],[Lain nya]])*Anggaran_BM[[#This Row],[Harga Satuan Paket MBG2]] -> 0 | U7: =Anggaran_BM[[#This Row],[Rencana Anggaran Biaya (RAB)]]-Anggaran_BM[[#This Row],[Aktual]] -> 0 | X7: =Anggaran_BM[[#This Row],[Hari/Tanggal]] -> 46030 | AA7: 0 | AC7: =Anggaran_Ops[[#This Row],[Rencana Anggaran Biaya (RAB)]]-Anggaran_Ops[[#This Row],[Aktual]] -> 0 | AF7: =Anggaran_BM[[#This Row],[Hari/Tanggal]] -> 46030 | AG7: 3000 | AH7: 2000 | AI7: =Anggaran_SM[[#This Row],[Jumlah Paket MBG]]*Anggaran_SM[[#This Row],[Harga Satuan Paket MBG]] -> 6000000 | AK7: =Anggaran_SM[[#This Row],[Rencana Anggaran Biaya (RAB)]]-Anggaran_SM[[#This Row],[Aktual]] -> 6000000
C8: =C7+1 -> 46031 | D8: =SUM(Anggaran_BM[[#This Row],[Balita]:[Santri]]) -> 0 | Q8: 8000 | R8: 10000 | S8: =(Anggaran_BM[[#This Row],[Balita]]+Anggaran_BM[[#This Row],[PAUD/ TK/RA]]+Anggaran_BM[[#This Row],[SD/MI 1-3]])*Anggaran_BM[[#This Row],[Harga Satuan Paket MBG]]+(Anggaran_BM[[#This Row],[SD/MI 4-6]]+Anggaran_BM[[#This Row],[SMP/ MTs]]+Anggaran_BM[[#This Row],[SMA/ MA/ SMK]]+Anggaran_BM[[#This Row],[SLB]]+Anggaran_BM[[#This Row],[Santri]]+Anggaran_BM[[#This Row],[Pend/ TK]]+Anggaran_BM[[#This Row],[Bumil]]+Anggaran_BM[[#This Row],[Busui]]+Anggaran_BM[[#This Row],[Lain nya]])*Anggaran_BM[[#This Row],[Harga Satuan Paket MBG2]] -> 0 | U8: =Anggaran_BM[[#This Row],[Rencana Anggaran Biaya (RAB)]]-Anggaran_BM[[#This Row],[Aktual]] -> 0 | X8: =Anggaran_BM[[#This Row],[Hari/Tanggal]] -> 46031 | AA8: 0 | AC8: =Anggaran_Ops[[#This Row],[Rencana Anggaran Biaya (RAB)]]-Anggaran_Ops[[#This Row],[Aktual]] -> 0 | AF8: =Anggaran_BM[[#This Row],[Hari/Tanggal]] -> 46031 | AG8: 3000 | AH8: 2000 | AI8: =Anggaran_SM[[#This Row],[Jumlah Paket MBG]]*Anggaran_SM[[#This Row],[Harga Satuan Paket MBG]] -> 6000000 | AK8: =Anggaran_SM[[#This Row],[Rencana Anggaran Biaya (RAB)]]-Anggaran_SM[[#This Row],[Aktual]] -> 6000000
C9: =C8+1 -> 46032 | D9: =SUM(Anggaran_BM[[#This Row],[Balita]:[Santri]]) -> 0 | Q9: 8000 | R9: 10000 | S9: =(Anggaran_BM[[#This Row],[Balita]]+Anggaran_BM[[#This Row],[PAUD/ TK/RA]]+Anggaran_BM[[#This Row],[SD/MI 1-3]])*Anggaran_BM[[#This Row],[Harga Satuan Paket MBG]]+(Anggaran_BM[[#This Row],[SD/MI 4-6]]+Anggaran_BM[[#This Row],[SMP/ MTs]]+Anggaran_BM[[#This Row],[SMA/ MA/ SMK]]+Anggaran_BM[[#This Row],[SLB]]+Anggaran_BM[[#This Row],[Santri]]+Anggaran_BM[[#This Row],[Pend/ TK]]+Anggaran_BM[[#This Row],[Bumil]]+Anggaran_BM[[#This Row],[Busui]]+Anggaran_BM[[#This Row],[Lain nya]])*Anggaran_BM[[#This Row],[Harga Satuan Paket MBG2]] -> 0 | U9: =Anggaran_BM[[#This Row],[Rencana Anggaran Biaya (RAB)]]-Anggaran_BM[[#This Row],[Aktual]] -> 0 | X9: =Anggaran_BM[[#This Row],[Hari/Tanggal]] -> 46032 | AA9: 0 | AC9: =Anggaran_Ops[[#This Row],[Rencana Anggaran Biaya (RAB)]]-Anggaran_Ops[[#This Row],[Aktual]] -> 0 | AF9: =Anggaran_BM[[#This Row],[Hari/Tanggal]] -> 46032 | AG9: 3000 | AH9: 2000 | AI9: =Anggaran_SM[[#This Row],[Jumlah Paket MBG]]*Anggaran_SM[[#This Row],[Harga Satuan Paket MBG]] -> 6000000 | AK9: =Anggaran_SM[[#This Row],[Rencana Anggaran Biaya (RAB)]]-Anggaran_SM[[#This Row],[Aktual]] -> 6000000
C10: Surplus/Utang | V10: =SUM(U4:U9) -> 0 | X10: Surplus/ Utang | AF10: Surplus/Utang
C11: =C9+2 -> 46034 | D11: =SUM(Anggaran_BM[[#This Row],[Balita]:[Santri]]) -> 0 | Q11: 8000 | R11: 10000 | S11: =(Anggaran_BM[[#This Row],[Balita]]+Anggaran_BM[[#This Row],[PAUD/ TK/RA]]+Anggaran_BM[[#This Row],[SD/MI 1-3]])*Anggaran_BM[[#This Row],[Harga Satuan Paket MBG]]+(Anggaran_BM[[#This Row],[SD/MI 4-6]]+Anggaran_BM[[#This Row],[SMP/ MTs]]+Anggaran_BM[[#This Row],[SMA/ MA/ SMK]]+Anggaran_BM[[#This Row],[SLB]]+Anggaran_BM[[#This Row],[Santri]]+Anggaran_BM[[#This Row],[Pend/ TK]]+Anggaran_BM[[#This Row],[Bumil]]+Anggaran_BM[[#This Row],[Busui]]+Anggaran_BM[[#This Row],[Lain nya]])*Anggaran_BM[[#This Row],[Harga Satuan Paket MBG2]] -> 0 | U11: =Anggaran_BM[[#This Row],[Rencana Anggaran Biaya (RAB)]]-Anggaran_BM[[#This Row],[Aktual]] -> 0 | X11: =Anggaran_BM[[#This Row],[Hari/Tanggal]] -> 46034 | AA11: 0 | AC11: =Anggaran_Ops[[#This Row],[Rencana Anggaran Biaya (RAB)]]-Anggaran_Ops[[#This Row],[Aktual]] -> 0 | AF11: =Anggaran_BM[[#This Row],[Hari/Tanggal]] -> 46034 | AG11: 3000 | AH11: 2000 | AI11: =Anggaran_SM[[#This Row],[Jumlah Paket MBG]]*Anggaran_SM[[#This Row],[Harga Satuan Paket MBG]] -> 6000000 | AK11: =Anggaran_SM[[#This Row],[Rencana Anggaran Biaya (RAB)]]-Anggaran_SM[[#This Row],[Aktual]] -> 6000000
C12: =C11+1 -> 46035 | D12: =SUM(Anggaran_BM[[#This Row],[Balita]:[Santri]]) -> 0 | Q12: 8000 | R12: 10000 | S12: =(Anggaran_BM[[#This Row],[Balita]]+Anggaran_BM[[#This Row],[PAUD/ TK/RA]]+Anggaran_BM[[#This Row],[SD/MI 1-3]])*Anggaran_BM[[#This Row],[Harga Satuan Paket MBG]]+(Anggaran_BM[[#This Row],[SD/MI 4-6]]+Anggaran_BM[[#This Row],[SMP/ MTs]]+Anggaran_BM[[#This Row],[SMA/ MA/ SMK]]+Anggaran_BM[[#This Row],[SLB]]+Anggaran_BM[[#This Row],[Santri]]+Anggaran_BM[[#This Row],[Pend/ TK]]+Anggaran_BM[[#This Row],[Bumil]]+Anggaran_BM[[#This Row],[Busui]]+Anggaran_BM[[#This Row],[Lain nya]])*Anggaran_BM[[#This Row],[Harga Satuan Paket MBG2]] -> 0 | U12: =Anggaran_BM[[#This Row],[Rencana Anggaran Biaya (RAB)]]-Anggaran_BM[[#This Row],[Aktual]] -> 0 | X12: =Anggaran_BM[[#This Row],[Hari/Tanggal]] -> 46035 | AA12: 0 | AC12: =Anggaran_Ops[[#This Row],[Rencana Anggaran Biaya (RAB)]]-Anggaran_Ops[[#This Row],[Aktual]] -> 0 | AF12: =Anggaran_BM[[#This Row],[Hari/Tanggal]] -> 46035 | AG12: 3000 | AH12: 2000 | AI12: =Anggaran_SM[[#This Row],[Jumlah Paket MBG]]*Anggaran_SM[[#This Row],[Harga Satuan Paket MBG]] -> 6000000 | AK12: =Anggaran_SM[[#This Row],[Rencana Anggaran Biaya (RAB)]]-Anggaran_SM[[#This Row],[Aktual]] -> 6000000
C13: =C12+1 -> 46036 | D13: =SUM(Anggaran_BM[[#This Row],[Balita]:[Santri]]) -> 0 | Q13: 8000 | R13: 10000 | S13: =(Anggaran_BM[[#This Row],[Balita]]+Anggaran_BM[[#This Row],[PAUD/ TK/RA]]+Anggaran_BM[[#This Row],[SD/MI 1-3]])*Anggaran_BM[[#This Row],[Harga Satuan Paket MBG]]+(Anggaran_BM[[#This Row],[SD/MI 4-6]]+Anggaran_BM[[#This Row],[SMP/ MTs]]+Anggaran_BM[[#This Row],[SMA/ MA/ SMK]]+Anggaran_BM[[#This Row],[SLB]]+Anggaran_BM[[#This Row],[Santri]]+Anggaran_BM[[#This Row],[Pend/ TK]]+Anggaran_BM[[#This Row],[Bumil]]+Anggaran_BM[[#This Row],[Busui]]+Anggaran_BM[[#This Row],[Lain nya]])*Anggaran_BM[[#This Row],[Harga Satuan Paket MBG2]] -> 0 | U13: =Anggaran_BM[[#This Row],[Rencana Anggaran Biaya (RAB)]]-Anggaran_BM[[#This Row],[Aktual]] -> 0 | X13: =Anggaran_BM[[#This Row],[Hari/Tanggal]] -> 46036 | AA13: 0 | AC13: =Anggaran_Ops[[#This Row],[Rencana Anggaran Biaya (RAB)]]-Anggaran_Ops[[#This Row],[Aktual]] -> 0 | AF13: =Anggaran_BM[[#This Row],[Hari/Tanggal]] -> 46036 | AG13: 3000 | AH13: 2000 | AI13: =Anggaran_SM[[#This Row],[Jumlah Paket MBG]]*Anggaran_SM[[#This Row],[Harga Satuan Paket MBG]] -> 6000000 | AK13: =Anggaran_SM[[#This Row],[Rencana Anggaran Biaya (RAB)]]-Anggaran_SM[[#This Row],[Aktual]] -> 6000000
C14: =C13+1 -> 46037 | D14: =SUM(Anggaran_BM[[#This Row],[Balita]:[Santri]]) -> 0 | Q14: 8000 | R14: 10000 | S14: =(Anggaran_BM[[#This Row],[Balita]]+Anggaran_BM[[#This Row],[PAUD/ TK/RA]]+Anggaran_BM[[#This Row],[SD/MI 1-3]])*Anggaran_BM[[#This Row],[Harga Satuan Paket MBG]]+(Anggaran_BM[[#This Row],[SD/MI 4-6]]+Anggaran_BM[[#This Row],[SMP/ MTs]]+Anggaran_BM[[#This Row],[SMA/ MA/ SMK]]+Anggaran_BM[[#This Row],[SLB]]+Anggaran_BM[[#This Row],[Santri]]+Anggaran_BM[[#This Row],[Pend/ TK]]+Anggaran_BM[[#This Row],[Bumil]]+Anggaran_BM[[#This Row],[Busui]]+Anggaran_BM[[#This Row],[Lain nya]])*Anggaran_BM[[#This Row],[Harga Satuan Paket MBG2]] -> 0 | U14: =Anggaran_BM[[#This Row],[Rencana Anggaran Biaya (RAB)]]-Anggaran_BM[[#This Row],[Aktual]] -> 0 | X14: =Anggaran_BM[[#This Row],[Hari/Tanggal]] -> 46037 | AA14: 0 | AC14: =Anggaran_Ops[[#This Row],[Rencana Anggaran Biaya (RAB)]]-Anggaran_Ops[[#This Row],[Aktual]] -> 0 | AF14: =Anggaran_BM[[#This Row],[Hari/Tanggal]] -> 46037 | AG14: 3000 | AH14: 2000 | AI14: =Anggaran_SM[[#This Row],[Jumlah Paket MBG]]*Anggaran_SM[[#This Row],[Harga Satuan Paket MBG]] -> 6000000 | AK14: =Anggaran_SM[[#This Row],[Rencana Anggaran Biaya (RAB)]]-Anggaran_SM[[#This Row],[Aktual]] -> 6000000
C15: =C14+1 -> 46038 | D15: =SUM(Anggaran_BM[[#This Row],[Balita]:[Santri]]) -> 0 | Q15: 8000 | R15: 10000 | S15: =(Anggaran_BM[[#This Row],[Balita]]+Anggaran_BM[[#This Row],[PAUD/ TK/RA]]+Anggaran_BM[[#This Row],[SD/MI 1-3]])*Anggaran_BM[[#This Row],[Harga Satuan Paket MBG]]+(Anggaran_BM[[#This Row],[SD/MI 4-6]]+Anggaran_BM[[#This Row],[SMP/ MTs]]+Anggaran_BM[[#This Row],[SMA/ MA/ SMK]]+Anggaran_BM[[#This Row],[SLB]]+Anggaran_BM[[#This Row],[Santri]]+Anggaran_BM[[#This Row],[Pend/ TK]]+Anggaran_BM[[#This Row],[Bumil]]+Anggaran_BM[[#This Row],[Busui]]+Anggaran_BM[[#This Row],[Lain nya]])*Anggaran_BM[[#This Row],[Harga Satuan Paket MBG2]] -> 0 | U15: =Anggaran_BM[[#This Row],[Rencana Anggaran Biaya (RAB)]]-Anggaran_BM[[#This Row],[Aktual]] -> 0 | X15: =Anggaran_BM[[#This Row],[Hari/Tanggal]] -> 46038 | AA15: 0 | AC15: =Anggaran_Ops[[#This Row],[Rencana Anggaran Biaya (RAB)]]-Anggaran_Ops[[#This Row],[Aktual]] -> 0 | AF15: =Anggaran_BM[[#This Row],[Hari/Tanggal]] -> 46038 | AG15: 3000 | AH15: 2000 | AI15: =Anggaran_SM[[#This Row],[Jumlah Paket MBG]]*Anggaran_SM[[#This Row],[Harga Satuan Paket MBG]] -> 6000000 | AK15: =Anggaran_SM[[#This Row],[Rencana Anggaran Biaya (RAB)]]-Anggaran_SM[[#This Row],[Aktual]] -> 6000000
C16: =C15+1 -> 46039 | D16: =SUM(Anggaran_BM[[#This Row],[Balita]:[Santri]]) -> 0 | Q16: 8000 | R16: 10000 | S16: =(Anggaran_BM[[#This Row],[Balita]]+Anggaran_BM[[#This Row],[PAUD/ TK/RA]]+Anggaran_BM[[#This Row],[SD/MI 1-3]])*Anggaran_BM[[#This Row],[Harga Satuan Paket MBG]]+(Anggaran_BM[[#This Row],[SD/MI 4-6]]+Anggaran_BM[[#This Row],[SMP/ MTs]]+Anggaran_BM[[#This Row],[SMA/ MA/ SMK]]+Anggaran_BM[[#This Row],[SLB]]+Anggaran_BM[[#This Row],[Santri]]+Anggaran_BM[[#This Row],[Pend/ TK]]+Anggaran_BM[[#This Row],[Bumil]]+Anggaran_BM[[#This Row],[Busui]]+Anggaran_BM[[#This Row],[Lain nya]])*Anggaran_BM[[#This Row],[Harga Satuan Paket MBG2]] -> 0 | U16: =Anggaran_BM[[#This Row],[Rencana Anggaran Biaya (RAB)]]-Anggaran_BM[[#This Row],[Aktual]] -> 0 | X16: =Anggaran_BM[[#This Row],[Hari/Tanggal]] -> 46039 | AA16: 0 | AC16: =Anggaran_Ops[[#This Row],[Rencana Anggaran Biaya (RAB)]]-Anggaran_Ops[[#This Row],[Aktual]] -> 0 | AF16: =Anggaran_BM[[#This Row],[Hari/Tanggal]] -> 46039 | AG16: 3000 | AH16: 2000 | AI16: =Anggaran_SM[[#This Row],[Jumlah Paket MBG]]*Anggaran_SM[[#This Row],[Harga Satuan Paket MBG]] -> 6000000 | AK16: =Anggaran_SM[[#This Row],[Rencana Anggaran Biaya (RAB)]]-Anggaran_SM[[#This Row],[Aktual]] -> 6000000
C17: Surplus/Utang | G17: =634+48 -> 682 | H17: =517+577 -> 1094 | I17: =75+74 -> 149 | V17: =SUM(U11:U16) -> 0 | X17: Surplus/Utang | AF17: Surplus/Utang
C18: Total | D18: =SUM(D4:D16) -> 0 | E18: =SUM(E4:E16) -> 0 | F18: =SUM(F4:F16) -> 0 | G18: =SUM(G4:G16) -> 0 | H18: =SUM(H4:H16) -> 0 | I18: =SUM(I4:I16) -> 0 | J18: =SUM(J4:J16) -> 0 | K18: =SUM(K4:K16) -> 0 | L18: =SUM(L4:L16) -> 0 | R18: - | S18: =SUM(S4:S16) -> 0 | T18: =SUBTOTAL(109,Anggaran_BM[Aktual]) -> 0 | U18: =SUBTOTAL(109,Anggaran_BM[Selisih]) -> 0 | X18: Total | AA18: =SUM(AA4:AA16) -> 0 | AB18: =SUBTOTAL(109,Anggaran_Ops[Aktual]) -> 0 | AC18: =SUM(AC4:AC16) -> 0 | AF18: Total | AG18: =SUM(AG4:AG16) -> 36000 | AH18: - | AI18: =SUM(AI4:AI16) -> 72000000 | AJ18: =SUM(AJ4:AJ16) -> 0 | AK18: =SUBTOTAL(109,Anggaran_SM[Selisih]) -> 72000000

Sheet Transaksi
C3: =IF(Setup!C6="","Nama SPPG.....",Setup!C6) -> Input Nama SPPG di sini
C4: INPUT DATA TRANSAKSI
C5: ="Periode : "&Setup!C15&" s.d. "&Setup!C16 -> Periode : 05-01-2026 s.d. 17-01-2026
C7: Daftar Kode Transaksi
C9: Tanggal (dd-mm-yyyy) | E9: Nomor Bukti | F9: Uraian Transaksi | G9: Debet (D) | H9: Kredit (K) | I9: Jenis Buku Pembantu | J9: Jika (D), masuk ke mana?, Jika (K), keluar dari mana? | K9: Akun Penerimaan/Pengeluaran | N9: Akun Kas | Q9: Catatan Pengeluaran | R9: Catatan Pengeluaran
A10: ROW | C10: 1 | E10: 2 | F10: 3 | G10: 4 | H10: 5 | I10: 6 | J10: 7 | K10: AKUN | L10: Debet | M10: Kredit | N10: AKUN | O10: Debet | P10: Kredit | Q10: Kredit | R10: Debet | W10: ROW
A11: =ROW() -> 11 | K11: =IF(I11="",0,I11) -> 0 | L11: =IF(H11=0,0,H11) -> 0 | M11: =IF(G11=0,0,G11) -> 0 | N11: =IF(J11="","",J11) | O11: =IF(G11=0,0,G11) -> 0 | P11: =IF(H11=0,0,H11) -> 0 | Q11: =IF(I11="Biaya Bahan Baku",H11,IF(I11="Biaya Operasional",H11,IF(I11="Biaya Insentif Fasilitas",H11,""))) | R11: =IF(I11="Dana Bantuan Pemerintah",G11,"") | S11: =IF(I11="Dana Bahan Baku","Bahan Baku",IF(I11="Biaya Bahan Baku","Bahan Baku",IF(I11="Dana Operasional","Operasional",IF(I11="Biaya Operasional","Operasional","")))) | T11: =IF(I11="Dana Insentif Fasilitas","Insentif Fasilitas",IF(I11="Biaya Insentif Fasilitas","Insentif Fasilitas","")) | U11: =IF(S11="",T11,S11) | V11: =IF(I11="Biaya Bahan Baku","Belanja",IF(I11="Biaya Operasional","Belanja",IF(I11="Biaya Insentif Fasilitas","Belanja",""))) | W11: =ROW() -> 11
A12: =ROW() -> 12 | K12: =IF(I12="",0,I12) -> 0 | L12: =IF(H12=0,0,H12) -> 0 | M12: =IF(G12=0,0,G12) -> 0 | N12: =IF(J12="","",J12) | O12: =IF(G12=0,0,G12) -> 0 | P12: =IF(H12=0,0,H12) -> 0 | Q12: =IF(I12="Biaya Bahan Baku",H12,IF(I12="Biaya Operasional",H12,IF(I12="Biaya Insentif Fasilitas",H12,""))) | R12: =IF(I12="Dana Bantuan Pemerintah",G12,"") | S12: =IF(I12="Dana Bahan Baku","Bahan Baku",IF(I12="Biaya Bahan Baku","Bahan Baku",IF(I12="Dana Operasional","Operasional",IF(I12="Biaya Operasional","Operasional","")))) | T12: =IF(I12="Dana Insentif Fasilitas","Insentif Fasilitas",IF(I12="Biaya Insentif Fasilitas","Insentif Fasilitas","")) | U12: =IF(S12="",T12,S12) | V12: =IF(I12="Biaya Bahan Baku","Belanja",IF(I12="Biaya Operasional","Belanja",IF(I12="Biaya Insentif Fasilitas","Belanja",""))) | W12: =ROW() -> 12
A13: =ROW() -> 13 | K13: =IF(I13="",0,I13) -> 0 | L13: =IF(H13=0,0,H13) -> 0 | M13: =IF(G13=0,0,G13) -> 0 | N13: =IF(J13="","",J13) | O13: =IF(G13=0,0,G13) -> 0 | P13: =IF(H13=0,0,H13) -> 0 | Q13: =IF(I13="Biaya Bahan Baku",H13,IF(I13="Biaya Operasional",H13,IF(I13="Biaya Insentif Fasilitas",H13,""))) | R13: =IF(I13="Dana Bantuan Pemerintah",G13,"") | S13: =IF(I13="Dana Bahan Baku","Bahan Baku",IF(I13="Biaya Bahan Baku","Bahan Baku",IF(I13="Dana Operasional","Operasional",IF(I13="Biaya Operasional","Operasional","")))) | T13: =IF(I13="Dana Insentif Fasilitas","Insentif Fasilitas",IF(I13="Biaya Insentif Fasilitas","Insentif Fasilitas","")) | U13: =IF(S13="",T13,S13) | V13: =IF(I13="Biaya Bahan Baku","Belanja",IF(I13="Biaya Operasional","Belanja",IF(I13="Biaya Insentif Fasilitas","Belanja",""))) | W13: =ROW() -> 13
A14: =ROW() -> 14 | K14: =IF(I14="",0,I14) -> 0 | L14: =IF(H14=0,0,H14) -> 0 | M14: =IF(G14=0,0,G14) -> 0 | N14: =IF(J14="","",J14) | O14: =IF(G14=0,0,G14) -> 0 | P14: =IF(H14=0,0,H14) -> 0 | Q14: =IF(I14="Biaya Bahan Baku",H14,IF(I14="Biaya Operasional",H14,IF(I14="Biaya Insentif Fasilitas",H14,""))) | R14: =IF(I14="Dana Bantuan Pemerintah",G14,"") | S14: =IF(I14="Dana Bahan Baku","Bahan Baku",IF(I14="Biaya Bahan Baku","Bahan Baku",IF(I14="Dana Operasional","Operasional",IF(I14="Biaya Operasional","Operasional","")))) | T14: =IF(I14="Dana Insentif Fasilitas","Insentif Fasilitas",IF(I14="Biaya Insentif Fasilitas","Insentif Fasilitas","")) | U14: =IF(S14="",T14,S14) | V14: =IF(I14="Biaya Bahan Baku","Belanja",IF(I14="Biaya Operasional","Belanja",IF(I14="Biaya Insentif Fasilitas","Belanja",""))) | W14: =ROW() -> 14
A15: =ROW() -> 15 | K15: =IF(I15="",0,I15) -> 0 | L15: =IF(H15=0,0,H15) -> 0 | M15: =IF(G15=0,0,G15) -> 0 | N15: =IF(J15="","",J15) | O15: =IF(G15=0,0,G15) -> 0 | P15: =IF(H15=0,0,H15) -> 0 | Q15: =IF(I15="Biaya Bahan Baku",H15,IF(I15="Biaya Operasional",H15,IF(I15="Biaya Insentif Fasilitas",H15,""))) | R15: =IF(I15="Dana Bantuan Pemerintah",G15,"") | S15: =IF(I15="Dana Bahan Baku","Bahan Baku",IF(I15="Biaya Bahan Baku","Bahan Baku",IF(I15="Dana Operasional","Operasional",IF(I15="Biaya Operasional","Operasional","")))) | T15: =IF(I15="Dana Insentif Fasilitas","Insentif Fasilitas",IF(I15="Biaya Insentif Fasilitas","Insentif Fasilitas","")) | U15: =IF(S15="",T15,S15) | V15: =IF(I15="Biaya Bahan Baku","Belanja",IF(I15="Biaya Operasional","Belanja",IF(I15="Biaya Insentif Fasilitas","Belanja",""))) | W15: =ROW() -> 15
A16: =ROW() -> 16 | K16: =IF(I16="",0,I16) -> 0 | L16: =IF(H16=0,0,H16) -> 0 | M16: =IF(G16=0,0,G16) -> 0 | N16: =IF(J16="","",J16) | O16: =IF(G16=0,0,G16) -> 0 | P16: =IF(H16=0,0,H16) -> 0 | Q16: =IF(I16="Biaya Bahan Baku",H16,IF(I16="Biaya Operasional",H16,IF(I16="Biaya Insentif Fasilitas",H16,""))) | R16: =IF(I16="Dana Bantuan Pemerintah",G16,"") | S16: =IF(I16="Dana Bahan Baku","Bahan Baku",IF(I16="Biaya Bahan Baku","Bahan Baku",IF(I16="Dana Operasional","Operasional",IF(I16="Biaya Operasional","Operasional","")))) | T16: =IF(I16="Dana Insentif Fasilitas","Insentif Fasilitas",IF(I16="Biaya Insentif Fasilitas","Insentif Fasilitas","")) | U16: =IF(S16="",T16,S16) | V16: =IF(I16="Biaya Bahan Baku","Belanja",IF(I16="Biaya Operasional","Belanja",IF(I16="Biaya Insentif Fasilitas","Belanja",""))) | W16: =ROW() -> 16
A17: =ROW() -> 17 | K17: =IF(I17="",0,I17) -> 0 | L17: =IF(H17=0,0,H17) -> 0 | M17: =IF(G17=0,0,G17) -> 0 | N17: =IF(J17="","",J17) | O17: =IF(G17=0,0,G17) -> 0 | P17: =IF(H17=0,0,H17) -> 0 | Q17: =IF(I17="Biaya Bahan Baku",H17,IF(I17="Biaya Operasional",H17,IF(I17="Biaya Insentif Fasilitas",H17,""))) | R17: =IF(I17="Dana Bantuan Pemerintah",G17,"") | S17: =IF(I17="Dana Bahan Baku","Bahan Baku",IF(I17="Biaya Bahan Baku","Bahan Baku",IF(I17="Dana Operasional","Operasional",IF(I17="Biaya Operasional","Operasional","")))) | T17: =IF(I17="Dana Insentif Fasilitas","Insentif Fasilitas",IF(I17="Biaya Insentif Fasilitas","Insentif Fasilitas","")) | U17: =IF(S17="",T17,S17) | V17: =IF(I17="Biaya Bahan Baku","Belanja",IF(I17="Biaya Operasional","Belanja",IF(I17="Biaya Insentif Fasilitas","Belanja",""))) | W17: =ROW() -> 17
A18: =ROW() -> 18 | K18: =IF(I18="",0,I18) -> 0 | L18: =IF(H18=0,0,H18) -> 0 | M18: =IF(G18=0,0,G18) -> 0 | N18: =IF(J18="","",J18) | O18: =IF(G18=0,0,G18) -> 0 | P18: =IF(H18=0,0,H18) -> 0 | Q18: =IF(I18="Biaya Bahan Baku",H18,IF(I18="Biaya Operasional",H18,IF(I18="Biaya Insentif Fasilitas",H18,""))) | R18: =IF(I18="Dana Bantuan Pemerintah",G18,"") | S18: =IF(I18="Dana Bahan Baku","Bahan Baku",IF(I18="Biaya Bahan Baku","Bahan Baku",IF(I18="Dana Operasional","Operasional",IF(I18="Biaya Operasional","Operasional","")))) | T18: =IF(I18="Dana Insentif Fasilitas","Insentif Fasilitas",IF(I18="Biaya Insentif Fasilitas","Insentif Fasilitas","")) | U18: =IF(S18="",T18,S18) | V18: =IF(I18="Biaya Bahan Baku","Belanja",IF(I18="Biaya Operasional","Belanja",IF(I18="Biaya Insentif Fasilitas","Belanja",""))) | W18: =ROW() -> 18
A19: =ROW() -> 19 | K19: =IF(I19="",0,I19) -> 0 | L19: =IF(H19=0,0,H19) -> 0 | M19: =IF(G19=0,0,G19) -> 0 | N19: =IF(J19="","",J19) | O19: =IF(G19=0,0,G19) -> 0 | P19: =IF(H19=0,0,H19) -> 0 | Q19: =IF(I19="Biaya Bahan Baku",H19,IF(I19="Biaya Operasional",H19,IF(I19="Biaya Insentif Fasilitas",H19,""))) | R19: =IF(I19="Dana Bantuan Pemerintah",G19,"") | S19: =IF(I19="Dana Bahan Baku","Bahan Baku",IF(I19="Biaya Bahan Baku","Bahan Baku",IF(I19="Dana Operasional","Operasional",IF(I19="Biaya Operasional","Operasional","")))) | T19: =IF(I19="Dana Insentif Fasilitas","Insentif Fasilitas",IF(I19="Biaya Insentif Fasilitas","Insentif Fasilitas","")) | U19: =IF(S19="",T19,S19) | V19: =IF(I19="Biaya Bahan Baku","Belanja",IF(I19="Biaya Operasional","Belanja",IF(I19="Biaya Insentif Fasilitas","Belanja",""))) | W19: =ROW() -> 19
A20: =ROW() -> 20 | K20: =IF(I20="",0,I20) -> 0 | L20: =IF(H20=0,0,H20) -> 0 | M20: =IF(G20=0,0,G20) -> 0 | N20: =IF(J20="","",J20) | O20: =IF(G20=0,0,G20) -> 0 | P20: =IF(H20=0,0,H20) -> 0 | Q20: =IF(I20="Biaya Bahan Baku",H20,IF(I20="Biaya Operasional",H20,IF(I20="Biaya Insentif Fasilitas",H20,""))) | R20: =IF(I20="Dana Bantuan Pemerintah",G20,"") | S20: =IF(I20="Dana Bahan Baku","Bahan Baku",IF(I20="Biaya Bahan Baku","Bahan Baku",IF(I20="Dana Operasional","Operasional",IF(I20="Biaya Operasional","Operasional","")))) | T20: =IF(I20="Dana Insentif Fasilitas","Insentif Fasilitas",IF(I20="Biaya Insentif Fasilitas","Insentif Fasilitas","")) | U20: =IF(S20="",T20,S20) | V20: =IF(I20="Biaya Bahan Baku","Belanja",IF(I20="Biaya Operasional","Belanja",IF(I20="Biaya Insentif Fasilitas","Belanja",""))) | W20: =ROW() -> 20
A21: =ROW() -> 21 | K21: =IF(I21="",0,I21) -> 0 | L21: =IF(H21=0,0,H21) -> 0 | M21: =IF(G21=0,0,G21) -> 0 | N21: =IF(J21="","",J21) | O21: =IF(G21=0,0,G21) -> 0 | P21: =IF(H21=0,0,H21) -> 0 | Q21: =IF(I21="Biaya Bahan Baku",H21,IF(I21="Biaya Operasional",H21,IF(I21="Biaya Insentif Fasilitas",H21,""))) | R21: =IF(I21="Dana Bantuan Pemerintah",G21,"") | S21: =IF(I21="Dana Bahan Baku","Bahan Baku",IF(I21="Biaya Bahan Baku","Bahan Baku",IF(I21="Dana Operasional","Operasional",IF(I21="Biaya Operasional","Operasional","")))) | T21: =IF(I21="Dana Insentif Fasilitas","Insentif Fasilitas",IF(I21="Biaya Insentif Fasilitas","Insentif Fasilitas","")) | U21: =IF(S21="",T21,S21) | V21: =IF(I21="Biaya Bahan Baku","Belanja",IF(I21="Biaya Operasional","Belanja",IF(I21="Biaya Insentif Fasilitas","Belanja",""))) | W21: =ROW() -> 21
A22: =ROW() -> 22 | K22: =IF(I22="",0,I22) -> 0 | L22: =IF(H22=0,0,H22) -> 0 | M22: =IF(G22=0,0,G22) -> 0 | N22: =IF(J22="","",J22) | O22: =IF(G22=0,0,G22) -> 0 | P22: =IF(H22=0,0,H22) -> 0 | Q22: =IF(I22="Biaya Bahan Baku",H22,IF(I22="Biaya Operasional",H22,IF(I22="Biaya Insentif Fasilitas",H22,""))) | R22: =IF(I22="Dana Bantuan Pemerintah",G22,"") | S22: =IF(I22="Dana Bahan Baku","Bahan Baku",IF(I22="Biaya Bahan Baku","Bahan Baku",IF(I22="Dana Operasional","Operasional",IF(I22="Biaya Operasional","Operasional","")))) | T22: =IF(I22="Dana Insentif Fasilitas","Insentif Fasilitas",IF(I22="Biaya Insentif Fasilitas","Insentif Fasilitas","")) | U22: =IF(S22="",T22,S22) | V22: =IF(I22="Biaya Bahan Baku","Belanja",IF(I22="Biaya Operasional","Belanja",IF(I22="Biaya Insentif Fasilitas","Belanja",""))) | W22: =ROW() -> 22
... A1010: =ROW() -> 1010 | K1010: =IF(I1010="",0,I1010) -> 0 | L1010: =IF(H1010=0,0,H1010) -> 0 | M1010: =IF(G1010=0,0,G1010) -> 0 | N1010: =IF(J1010="","",J1010) | O1010: =IF(G1010=0,0,G1010) -> 0 | P1010: =IF(H1010=0,0,H1010) -> 0 | Q1010: =IF(I1010="Biaya Bahan Baku",H1010,IF(I1010="Biaya Operasional",H1010,IF(I1010="Biaya Insentif Fasilitas",H1010,""))) | R1010: =IF(I1010="Dana Bantuan Pemerintah",G1010,"") | S1010: =IF(I1010="Dana Bahan Baku","Bahan Baku",IF(I1010="Biaya Bahan Baku","Bahan Baku",IF(I1010="Dana Operasional","Operasional",IF(I1010="Biaya Operasional","Operasional","")))) | T1010: =IF(I1010="Dana Insentif Fasilitas","Insentif Fasilitas",IF(I1010="Biaya Insentif Fasilitas","Insentif Fasilitas","")) | U1010: =IF(S1010="",T1010,S1010) | V1010: =IF(I1010="Biaya Bahan Baku","Belanja",IF(I1010="Biaya Operasional","Belanja",IF(I1010="Biaya Insentif Fasilitas","Belanja",""))) | W1010: =ROW() -> 1010
A1011: xx | K1011: =IF(I1011="",0,I1011) -> 0 | L1011: =IF(H1011=0,0,H1011) -> 0 | M1011: =IF(G1011=0,0,G1011) -> 0 | N1011: =IF(J1011="","",J1011) | O1011: =IF(G1011=0,0,G1011) -> 0 | P1011: =IF(H1011=0,0,H1011) -> 0 | Q1011: =IF(I1011="Biaya Bahan Baku",H1011,IF(I1011="Biaya Operasional",H1011,IF(I1011="Biaya Insentif Fasilitas",H1011,""))) | R1011: =IF(I1011="Dana Bantuan Pemerintah",G1011,"") | S1011: =IF(I1011="Dana Bahan Baku","Bahan Baku",IF(I1011="Biaya Bahan Baku","Bahan Baku",IF(I1011="Dana Operasional","Operasional",IF(I1011="Biaya Operasional","Operasional","")))) | T1011: =IF(I1011="Dana Insentif Fasilitas","Insentif Fasilitas",IF(I1011="Biaya Insentif Fasilitas","Insentif Fasilitas","")) | U1011: =IF(S1011="",T1011,S1011) | V1011: =IF(I1011="Biaya Bahan Baku","Belanja",IF(I1011="Biaya Operasional","Belanja",IF(I1011="Biaya Insentif Fasilitas","Belanja",""))) | W1011: =ROW() -> 1011
K1012: =IF(I1012="",0,I1012) -> 0 | L1012: =IF(H1012=0,0,H1012) -> 0 | M1012: =IF(G1012=0,0,G1012) -> 0 | N1012: =IF(J1012="","",J1012) | O1012: =IF(G1012=0,0,G1012) -> 0 | P1012: =IF(H1012=0,0,H1012) -> 0 | Q1012: =IF(I1012="Biaya Bahan Baku",H1012,IF(I1012="Biaya Operasional",H1012,IF(I1012="Biaya Insentif Fasilitas",H1012,""))) | R1012: =IF(I1012="Dana Bantuan Pemerintah",G1012,"") | S1012: =IF(I1012="Dana Bahan Baku","Bahan Baku",IF(I1012="Biaya Bahan Baku","Bahan Baku",IF(I1012="Dana Operasional","Operasional",IF(I1012="Biaya Operasional","Operasional","")))) | T1012: =IF(I1012="Dana Insentif Fasilitas","Insentif Fasilitas",IF(I1012="Biaya Insentif Fasilitas","Insentif Fasilitas","")) | U1012: =IF(S1012="",T1012,S1012) | V1012: =IF(I1012="Biaya Bahan Baku","Belanja",IF(I1012="Biaya Operasional","Belanja",IF(I1012="Biaya Insentif Fasilitas","Belanja",""))) | W1012: =ROW() -> 1012
K1013: =IF(I1013="",0,I1013) -> 0 | L1013: =IF(H1013=0,0,H1013) -> 0 | M1013: =IF(G1013=0,0,G1013) -> 0 | N1013: =IF(J1013="","",J1013) | O1013: =IF(G1013=0,0,G1013) -> 0 | P1013: =IF(H1013=0,0,H1013) -> 0 | Q1013: =IF(I1013="Biaya Bahan Baku",H1013,IF(I1013="Biaya Operasional",H1013,IF(I1013="Biaya Insentif Fasilitas",H1013,""))) | R1013: =IF(I1013="Dana Bantuan Pemerintah",G1013,"") | S1013: =IF(I1013="Dana Bahan Baku","Bahan Baku",IF(I1013="Biaya Bahan Baku","Bahan Baku",IF(I1013="Dana Operasional","Operasional",IF(I1013="Biaya Operasional","Operasional","")))) | T1013: =IF(I1013="Dana Insentif Fasilitas","Insentif Fasilitas",IF(I1013="Biaya Insentif Fasilitas","Insentif Fasilitas","")) | U1013: =IF(S1013="",T1013,S1013) | V1013: =IF(I1013="Biaya Bahan Baku","Belanja",IF(I1013="Biaya Operasional","Belanja",IF(I1013="Biaya Insentif Fasilitas","Belanja",""))) | W1013: =ROW() -> 1013
K1014: =IF(I1014="",0,I1014) -> 0 | L1014: =IF(H1014=0,0,H1014) -> 0 | M1014: =IF(G1014=0,0,G1014) -> 0 | N1014: =IF(J1014="","",J1014) | O1014: =IF(G1014=0,0,G1014) -> 0 | P1014: =IF(H1014=0,0,H1014) -> 0 | Q1014: =IF(I1014="Biaya Bahan Baku",H1014,IF(I1014="Biaya Operasional",H1014,IF(I1014="Biaya Insentif Fasilitas",H1014,""))) | R1014: =IF(I1014="Dana Bantuan Pemerintah",G1014,"") | S1014: =IF(I1014="Dana Bahan Baku","Bahan Baku",IF(I1014="Biaya Bahan Baku","Bahan Baku",IF(I1014="Dana Operasional","Operasional",IF(I1014="Biaya Operasional","Operasional","")))) | T1014: =IF(I1014="Dana Insentif Fasilitas","Insentif Fasilitas",IF(I1014="Biaya Insentif Fasilitas","Insentif Fasilitas","")) | U1014: =IF(S1014="",T1014,S1014) | V1014: =IF(I1014="Biaya Bahan Baku","Belanja",IF(I1014="Biaya Operasional","Belanja",IF(I1014="Biaya Insentif Fasilitas","Belanja",""))) | W1014: =ROW() -> 1014
K1015: =IF(I1015="",0,I1015) -> 0 | L1015: =IF(H1015=0,0,H1015) -> 0 | M1015: =IF(G1015=0,0,G1015) -> 0 | N1015: =IF(J1015="","",J1015) | O1015: =IF(G1015=0,0,G1015) -> 0 | P1015: =IF(H1015=0,0,H1015) -> 0 | Q1015: =IF(I1015="Biaya Bahan Baku",H1015,IF(I1015="Biaya Operasional",H1015,IF(I1015="Biaya Insentif Fasilitas",H1015,""))) | R1015: =IF(I1015="Dana Bantuan Pemerintah",G1015,"") | S1015: =IF(I1015="Dana Bahan Baku","Bahan Baku",IF(I1015="Biaya Bahan Baku","Bahan Baku",IF(I1015="Dana Operasional","Operasional",IF(I1015="Biaya Operasional","Operasional","")))) | T1015: =IF(I1015="Dana Insentif Fasilitas","Insentif Fasilitas",IF(I1015="Biaya Insentif Fasilitas","Insentif Fasilitas","")) | U1015: =IF(S1015="",T1015,S1015) | V1015: =IF(I1015="Biaya Bahan Baku","Belanja",IF(I1015="Biaya Operasional","Belanja",IF(I1015="Biaya Insentif Fasilitas","Belanja",""))) | W1015: =ROW() -> 1015
K1016: =IF(I1016="",0,I1016) -> 0 | L1016: =IF(H1016=0,0,H1016) -> 0 | M1016: =IF(G1016=0,0,G1016) -> 0 | N1016: =IF(J1016="","",J1016) | O1016: =IF(G1016=0,0,G1016) -> 0 | P1016: =IF(H1016=0,0,H1016) -> 0 | Q1016: =IF(I1016="Biaya Bahan Baku",H1016,IF(I1016="Biaya Operasional",H1016,IF(I1016="Biaya Insentif Fasilitas",H1016,""))) | R1016: =IF(I1016="Dana Bantuan Pemerintah",G1016,"") | S1016: =IF(I1016="Dana Bahan Baku","Bahan Baku",IF(I1016="Biaya Bahan Baku","Bahan Baku",IF(I1016="Dana Operasional","Operasional",IF(I1016="Biaya Operasional","Operasional","")))) | T1016: =IF(I1016="Dana Insentif Fasilitas","Insentif Fasilitas",IF(I1016="Biaya Insentif Fasilitas","Insentif Fasilitas","")) | U1016: =IF(S1016="",T1016,S1016) | V1016: =IF(I1016="Biaya Bahan Baku","Belanja",IF(I1016="Biaya Operasional","Belanja",IF(I1016="Biaya Insentif Fasilitas","Belanja",""))) | W1016: =ROW() -> 1016
K1017: =IF(I1017="",0,I1017) -> 0 | L1017: =IF(H1017=0,0,H1017) -> 0 | M1017: =IF(G1017=0,0,G1017) -> 0 | N1017: =IF(J1017="","",J1017) | O1017: =IF(G1017=0,0,G1017) -> 0 | P1017: =IF(H1017=0,0,H1017) -> 0 | Q1017: =IF(I1017="Biaya Bahan Baku",H1017,IF(I1017="Biaya Operasional",H1017,IF(I1017="Biaya Insentif Fasilitas",H1017,""))) | R1017: =IF(I1017="Dana Bantuan Pemerintah",G1017,"") | S1017: =IF(I1017="Dana Bahan Baku","Bahan Baku",IF(I1017="Biaya Bahan Baku","Bahan Baku",IF(I1017="Dana Operasional","Operasional",IF(I1017="Biaya Operasional","Operasional","")))) | T1017: =IF(I1017="Dana Insentif Fasilitas","Insentif Fasilitas",IF(I1017="Biaya Insentif Fasilitas","Insentif Fasilitas","")) | U1017: =IF(S1017="",T1017,S1017) | V1017: =IF(I1017="Biaya Bahan Baku","Belanja",IF(I1017="Biaya Operasional","Belanja",IF(I1017="Biaya Insentif Fasilitas","Belanja",""))) | W1017: =ROW() -> 1017
K1018: =IF(I1018="",0,I1018) -> 0 | L1018: =IF(H1018=0,0,H1018) -> 0 | M1018: =IF(G1018=0,0,G1018) -> 0 | N1018: =IF(J1018="","",J1018) | O1018: =IF(G1018=0,0,G1018) -> 0 | P1018: =IF(H1018=0,0,H1018) -> 0 | Q1018: =IF(I1018="Biaya Bahan Baku",H1018,IF(I1018="Biaya Operasional",H1018,IF(I1018="Biaya Insentif Fasilitas",H1018,""))) | R1018: =IF(I1018="Dana Bantuan Pemerintah",G1018,"") | S1018: =IF(I1018="Dana Bahan Baku","Bahan Baku",IF(I1018="Biaya Bahan Baku","Bahan Baku",IF(I1018="Dana Operasional","Operasional",IF(I1018="Biaya Operasional","Operasional","")))) | T1018: =IF(I1018="Dana Insentif Fasilitas","Insentif Fasilitas",IF(I1018="Biaya Insentif Fasilitas","Insentif Fasilitas","")) | U1018: =IF(S1018="",T1018,S1018) | V1018: =IF(I1018="Biaya Bahan Baku","Belanja",IF(I1018="Biaya Operasional","Belanja",IF(I1018="Biaya Insentif Fasilitas","Belanja",""))) | W1018: =ROW() -> 1018
K1019: =IF(I1019="",0,I1019) -> 0 | L1019: =IF(H1019=0,0,H1019) -> 0 | M1019: =IF(G1019=0,0,G1019) -> 0 | N1019: =IF(J1019="","",J1019) | O1019: =IF(G1019=0,0,G1019) -> 0 | P1019: =IF(H1019=0,0,H1019) -> 0 | Q1019: =IF(I1019="Biaya Bahan Baku",H1019,IF(I1019="Biaya Operasional",H1019,IF(I1019="Biaya Insentif Fasilitas",H1019,""))) | R1019: =IF(I1019="Dana Bantuan Pemerintah",G1019,"") | S1019: =IF(I1019="Dana Bahan Baku","Bahan Baku",IF(I1019="Biaya Bahan Baku","Bahan Baku",IF(I1019="Dana Operasional","Operasional",IF(I1019="Biaya Operasional","Operasional","")))) | T1019: =IF(I1019="Dana Insentif Fasilitas","Insentif Fasilitas",IF(I1019="Biaya Insentif Fasilitas","Insentif Fasilitas","")) | U1019: =IF(S1019="",T1019,S1019) | V1019: =IF(I1019="Biaya Bahan Baku","Belanja",IF(I1019="Biaya Operasional","Belanja",IF(I1019="Biaya Insentif Fasilitas","Belanja",""))) | W1019: =ROW() -> 1019
K1020: =IF(I1020="",0,I1020) -> 0 | L1020: =IF(H1020=0,0,H1020) -> 0 | M1020: =IF(G1020=0,0,G1020) -> 0 | N1020: =IF(J1020="","",J1020) | O1020: =IF(G1020=0,0,G1020) -> 0 | P1020: =IF(H1020=0,0,H1020) -> 0 | Q1020: =IF(I1020="Biaya Bahan Baku",H1020,IF(I1020="Biaya Operasional",H1020,IF(I1020="Biaya Insentif Fasilitas",H1020,""))) | R1020: =IF(I1020="Dana Bantuan Pemerintah",G1020,"") | S1020: =IF(I1020="Dana Bahan Baku","Bahan Baku",IF(I1020="Biaya Bahan Baku","Bahan Baku",IF(I1020="Dana Operasional","Operasional",IF(I1020="Biaya Operasional","Operasional","")))) | T1020: =IF(I1020="Dana Insentif Fasilitas","Insentif Fasilitas",IF(I1020="Biaya Insentif Fasilitas","Insentif Fasilitas","")) | U1020: =IF(S1020="",T1020,S1020) | V1020: =IF(I1020="Biaya Bahan Baku","Belanja",IF(I1020="Biaya Operasional","Belanja",IF(I1020="Biaya Insentif Fasilitas","Belanja",""))) | W1020: =ROW() -> 1020
K1021: =IF(I1021="",0,I1021) -> 0 | L1021: =IF(H1021=0,0,H1021) -> 0 | M1021: =IF(G1021=0,0,G1021) -> 0 | N1021: =IF(J1021="","",J1021) | O1021: =IF(G1021=0,0,G1021) -> 0 | P1021: =IF(H1021=0,0,H1021) -> 0 | Q1021: =IF(I1021="Biaya Bahan Baku",H1021,IF(I1021="Biaya Operasional",H1021,IF(I1021="Biaya Insentif Fasilitas",H1021,""))) | R1021: =IF(I1021="Dana Bantuan Pemerintah",G1021,"") | S1021: =IF(I1021="Dana Bahan Baku","Bahan Baku",IF(I1021="Biaya Bahan Baku","Bahan Baku",IF(I1021="Dana Operasional","Operasional",IF(I1021="Biaya Operasional","Operasional","")))) | T1021: =IF(I1021="Dana Insentif Fasilitas","Insentif Fasilitas",IF(I1021="Biaya Insentif Fasilitas","Insentif Fasilitas","")) | U1021: =IF(S1021="",T1021,S1021) | V1021: =IF(I1021="Biaya Bahan Baku","Belanja",IF(I1021="Biaya Operasional","Belanja",IF(I1021="Biaya Insentif Fasilitas","Belanja",""))) | W1021: =ROW() -> 1021
K1022: =IF(I1022="",0,I1022) -> 0 | L1022: =IF(H1022=0,0,H1022) -> 0 | M1022: =IF(G1022=0,0,G1022) -> 0 | N1022: =IF(J1022="","",J1022) | O1022: =IF(G1022=0,0,G1022) -> 0 | P1022: =IF(H1022=0,0,H1022) -> 0 | Q1022: =IF(I1022="Biaya Bahan Baku",H1022,IF(I1022="Biaya Operasional",H1022,IF(I1022="Biaya Insentif Fasilitas",H1022,""))) | R1022: =IF(I1022="Dana Bantuan Pemerintah",G1022,"") | S1022: =IF(I1022="Dana Bahan Baku","Bahan Baku",IF(I1022="Biaya Bahan Baku","Bahan Baku",IF(I1022="Dana Operasional","Operasional",IF(I1022="Biaya Operasional","Operasional","")))) | T1022: =IF(I1022="Dana Insentif Fasilitas","Insentif Fasilitas",IF(I1022="Biaya Insentif Fasilitas","Insentif Fasilitas","")) | U1022: =IF(S1022="",T1022,S1022) | V1022: =IF(I1022="Biaya Bahan Baku","Belanja",IF(I1022="Biaya Operasional","Belanja",IF(I1022="Biaya Insentif Fasilitas","Belanja",""))) | W1022: =ROW() -> 1022
K1023: =IF(I1023="",0,I1023) -> 0 | L1023: =IF(H1023=0,0,H1023) -> 0 | M1023: =IF(G1023=0,0,G1023) -> 0 | N1023: =IF(J1023="","",J1023) | O1023: =IF(G1023=0,0,G1023) -> 0 | P1023: =IF(H1023=0,0,H1023) -> 0 | Q1023: =IF(I1023="Biaya Bahan Baku",H1023,IF(I1023="Biaya Operasional",H1023,IF(I1023="Biaya Insentif Fasilitas",H1023,""))) | R1023: =IF(I1023="Dana Bantuan Pemerintah",G1023,"") | S1023: =IF(I1023="Dana Bahan Baku","Bahan Baku",IF(I1023="Biaya Bahan Baku","Bahan Baku",IF(I1023="Dana Operasional","Operasional",IF(I1023="Biaya Operasional","Operasional","")))) | T1023: =IF(I1023="Dana Insentif Fasilitas","Insentif Fasilitas",IF(I1023="Biaya Insentif Fasilitas","Insentif Fasilitas","")) | U1023: =IF(S1023="",T1023,S1023) | V1023: =IF(I1023="Biaya Bahan Baku","Belanja",IF(I1023="Biaya Operasional","Belanja",IF(I1023="Biaya Insentif Fasilitas","Belanja",""))) | W1023: =ROW() -> 1023
... K1152: =IF(I1152="",0,I1152) -> 0 | L1152: =IF(H1152=0,0,H1152) -> 0 | M1152: =IF(G1152=0,0,G1152) -> 0 | N1152: =IF(J1152="","",J1152) | O1152: =IF(G1152=0,0,G1152) -> 0 | P1152: =IF(H1152=0,0,H1152) -> 0 | Q1152: =IF(I1152="Biaya Bahan Baku",H1152,IF(I1152="Biaya Operasional",H1152,IF(I1152="Biaya Insentif Fasilitas",H1152,""))) | R1152: =IF(I1152="Dana Bantuan Pemerintah",G1152,"") | S1152: =IF(I1152="Dana Bahan Baku","Bahan Baku",IF(I1152="Biaya Bahan Baku","Bahan Baku",IF(I1152="Dana Operasional","Operasional",IF(I1152="Biaya Operasional","Operasional","")))) | T1152: =IF(I1152="Dana Insentif Fasilitas","Insentif Fasilitas",IF(I1152="Biaya Insentif Fasilitas","Insentif Fasilitas","")) | U1152: =IF(S1152="",T1152,S1152) | V1152: =IF(I1152="Biaya Bahan Baku","Belanja",IF(I1152="Biaya Operasional","Belanja",IF(I1152="Biaya Insentif Fasilitas","Belanja",""))) | W1152: =ROW() -> 1152

Sheet BKU
C5: BUKU KAS UMUM
C6: =Transaksi!C5 -> Periode : 05-01-2026 s.d. 17-01-2026
C9: Nama SPPG | E9: =": "&Setup!C6 -> : Input Nama SPPG di sini
C10: ID SPPG | E10: =": "&Setup!C7 -> : | H10: Saldo Awal | I10: =IF(C5="","",VLOOKUP(C5,'Saldo Buku'!C8:D28,2,FALSE)) -> 0
C11: Alamat | E11: =": "&Setup!C8 -> : | H11: Saldo Akhir | I11: =I10+SUM(G16:G215)-SUM(H16:H215) -> 0
C13: Bulan | D13: Tgl | E13: No. Bukti | F13: Uraian Transaksi | G13: Debet | H13: Kredit | I13: Saldo
C14: 1 | D14: 2 | E14: 2 | F14: 3 | G14: 4 | H14: 5 | I14: 6
A15: R | C15: x | F15: SALDO AWAL BULAN BERJALAN | G15: =I10 -> 0 | H15: 0 | I15: =I10 -> 0
A16: =IF(Transaksi!J11="","",Transaksi!A11) | C16: =IFERROR(VLOOKUP(A16,Transaksi!$A$11:$C$1000,3,FALSE),"") | D16: =IFERROR(VLOOKUP(A16,Transaksi!$A$11:$D$1000,4,FALSE),"") | E16: =IFERROR(VLOOKUP(A16,Transaksi!$A$11:$E$1000,5,FALSE),"") | F16: =IFERROR(VLOOKUP(A16,Transaksi!$A$11:$F$1000,6,FALSE),"") | G16: =IFERROR(VLOOKUP(A16,Transaksi!$A$11:$G$1000,7,FALSE),"") | H16: =IFERROR(VLOOKUP(A16,Transaksi!$A$11:$H$1000,8,FALSE),"") | I16: =IF(F16="","",I15+G16-H16)
A17: =IF(Transaksi!J12="","",Transaksi!A12) | C17: =IFERROR(VLOOKUP(A17,Transaksi!$A$11:$C$1000,3,FALSE),"") | D17: =IFERROR(VLOOKUP(A17,Transaksi!$A$11:$D$1000,4,FALSE),"") | E17: =IFERROR(VLOOKUP(A17,Transaksi!$A$11:$E$1000,5,FALSE),"") | F17: =IFERROR(VLOOKUP(A17,Transaksi!$A$11:$F$1000,6,FALSE),"") | G17: =IFERROR(VLOOKUP(A17,Transaksi!$A$11:$G$1000,7,FALSE),"") | H17: =IFERROR(VLOOKUP(A17,Transaksi!$A$11:$H$1000,8,FALSE),"") | I17: =IF(F17="","",I16+G17-H17)
A18: =IF(Transaksi!J13="","",Transaksi!A13) | C18: =IFERROR(VLOOKUP(A18,Transaksi!$A$11:$C$1000,3,FALSE),"") | D18: =IFERROR(VLOOKUP(A18,Transaksi!$A$11:$D$1000,4,FALSE),"") | E18: =IFERROR(VLOOKUP(A18,Transaksi!$A$11:$E$1000,5,FALSE),"") | F18: =IFERROR(VLOOKUP(A18,Transaksi!$A$11:$F$1000,6,FALSE),"") | G18: =IFERROR(VLOOKUP(A18,Transaksi!$A$11:$G$1000,7,FALSE),"") | H18: =IFERROR(VLOOKUP(A18,Transaksi!$A$11:$H$1000,8,FALSE),"") | I18: =IF(F18="","",I17+G18-H18)
A19: =IF(Transaksi!J14="","",Transaksi!A14) | C19: =IFERROR(VLOOKUP(A19,Transaksi!$A$11:$C$1000,3,FALSE),"") | D19: =IFERROR(VLOOKUP(A19,Transaksi!$A$11:$D$1000,4,FALSE),"") | E19: =IFERROR(VLOOKUP(A19,Transaksi!$A$11:$E$1000,5,FALSE),"") | F19: =IFERROR(VLOOKUP(A19,Transaksi!$A$11:$F$1000,6,FALSE),"") | G19: =IFERROR(VLOOKUP(A19,Transaksi!$A$11:$G$1000,7,FALSE),"") | H19: =IFERROR(VLOOKUP(A19,Transaksi!$A$11:$H$1000,8,FALSE),"") | I19: =IF(F19="","",I18+G19-H19)
A20: =IF(Transaksi!J15="","",Transaksi!A15) | C20: =IFERROR(VLOOKUP(A20,Transaksi!$A$11:$C$1000,3,FALSE),"") | D20: =IFERROR(VLOOKUP(A20,Transaksi!$A$11:$D$1000,4,FALSE),"") | E20: =IFERROR(VLOOKUP(A20,Transaksi!$A$11:$E$1000,5,FALSE),"") | F20: =IFERROR(VLOOKUP(A20,Transaksi!$A$11:$F$1000,6,FALSE),"") | G20: =IFERROR(VLOOKUP(A20,Transaksi!$A$11:$G$1000,7,FALSE),"") | H20: =IFERROR(VLOOKUP(A20,Transaksi!$A$11:$H$1000,8,FALSE),"") | I20: =IF(F20="","",I19+G20-H20)
A21: =IF(Transaksi!J16="","",Transaksi!A16) | C21: =IFERROR(VLOOKUP(A21,Transaksi!$A$11:$C$1000,3,FALSE),"") | D21: =IFERROR(VLOOKUP(A21,Transaksi!$A$11:$D$1000,4,FALSE),"") | E21: =IFERROR(VLOOKUP(A21,Transaksi!$A$11:$E$1000,5,FALSE),"") | F21: =IFERROR(VLOOKUP(A21,Transaksi!$A$11:$F$1000,6,FALSE),"") | G21: =IFERROR(VLOOKUP(A21,Transaksi!$A$11:$G$1000,7,FALSE),"") | H21: =IFERROR(VLOOKUP(A21,Transaksi!$A$11:$H$1000,8,FALSE),"") | I21: =IF(F21="","",I20+G21-H21)
A22: =IF(Transaksi!J17="","",Transaksi!A17) | C22: =IFERROR(VLOOKUP(A22,Transaksi!$A$11:$C$1000,3,FALSE),"") | D22: =IFERROR(VLOOKUP(A22,Transaksi!$A$11:$D$1000,4,FALSE),"") | E22: =IFERROR(VLOOKUP(A22,Transaksi!$A$11:$E$1000,5,FALSE),"") | F22: =IFERROR(VLOOKUP(A22,Transaksi!$A$11:$F$1000,6,FALSE),"") | G22: =IFERROR(VLOOKUP(A22,Transaksi!$A$11:$G$1000,7,FALSE),"") | H22: =IFERROR(VLOOKUP(A22,Transaksi!$A$11:$H$1000,8,FALSE),"") | I22: =IF(F22="","",I21+G22-H22)
A23: =IF(Transaksi!J18="","",Transaksi!A18) | C23: =IFERROR(VLOOKUP(A23,Transaksi!$A$11:$C$1000,3,FALSE),"") | D23: =IFERROR(VLOOKUP(A23,Transaksi!$A$11:$D$1000,4,FALSE),"") | E23: =IFERROR(VLOOKUP(A23,Transaksi!$A$11:$E$1000,5,FALSE),"") | F23: =IFERROR(VLOOKUP(A23,Transaksi!$A$11:$F$1000,6,FALSE),"") | G23: =IFERROR(VLOOKUP(A23,Transaksi!$A$11:$G$1000,7,FALSE),"") | H23: =IFERROR(VLOOKUP(A23,Transaksi!$A$11:$H$1000,8,FALSE),"") | I23: =IF(F23="","",I22+G23-H23)
A24: =IF(Transaksi!J19="","",Transaksi!A19) | C24: =IFERROR(VLOOKUP(A24,Transaksi!$A$11:$C$1000,3,FALSE),"") | D24: =IFERROR(VLOOKUP(A24,Transaksi!$A$11:$D$1000,4,FALSE),"") | E24: =IFERROR(VLOOKUP(A24,Transaksi!$A$11:$E$1000,5,FALSE),"") | F24: =IFERROR(VLOOKUP(A24,Transaksi!$A$11:$F$1000,6,FALSE),"") | G24: =IFERROR(VLOOKUP(A24,Transaksi!$A$11:$G$1000,7,FALSE),"") | H24: =IFERROR(VLOOKUP(A24,Transaksi!$A$11:$H$1000,8,FALSE),"") | I24: =IF(F24="","",I23+G24-H24)
A25: =IF(Transaksi!J20="","",Transaksi!A20) | C25: =IFERROR(VLOOKUP(A25,Transaksi!$A$11:$C$1000,3,FALSE),"") | D25: =IFERROR(VLOOKUP(A25,Transaksi!$A$11:$D$1000,4,FALSE),"") | E25: =IFERROR(VLOOKUP(A25,Transaksi!$A$11:$E$1000,5,FALSE),"") | F25: =IFERROR(VLOOKUP(A25,Transaksi!$A$11:$F$1000,6,FALSE),"") | G25: =IFERROR(VLOOKUP(A25,Transaksi!$A$11:$G$1000,7,FALSE),"") | H25: =IFERROR(VLOOKUP(A25,Transaksi!$A$11:$H$1000,8,FALSE),"") | I25: =IF(F25="","",I24+G25-H25)
A26: =IF(Transaksi!J21="","",Transaksi!A21) | C26: =IFERROR(VLOOKUP(A26,Transaksi!$A$11:$C$1000,3,FALSE),"") | D26: =IFERROR(VLOOKUP(A26,Transaksi!$A$11:$D$1000,4,FALSE),"") | E26: =IFERROR(VLOOKUP(A26,Transaksi!$A$11:$E$1000,5,FALSE),"") | F26: =IFERROR(VLOOKUP(A26,Transaksi!$A$11:$F$1000,6,FALSE),"") | G26: =IFERROR(VLOOKUP(A26,Transaksi!$A$11:$G$1000,7,FALSE),"") | H26: =IFERROR(VLOOKUP(A26,Transaksi!$A$11:$H$1000,8,FALSE),"") | I26: =IF(F26="","",I25+G26-H26)
A27: =IF(Transaksi!J22="","",Transaksi!A22) | C27: =IFERROR(VLOOKUP(A27,Transaksi!$A$11:$C$1000,3,FALSE),"") | D27: =IFERROR(VLOOKUP(A27,Transaksi!$A$11:$D$1000,4,FALSE),"") | E27: =IFERROR(VLOOKUP(A27,Transaksi!$A$11:$E$1000,5,FALSE),"") | F27: =IFERROR(VLOOKUP(A27,Transaksi!$A$11:$F$1000,6,FALSE),"") | G27: =IFERROR(VLOOKUP(A27,Transaksi!$A$11:$G$1000,7,FALSE),"") | H27: =IFERROR(VLOOKUP(A27,Transaksi!$A$11:$H$1000,8,FALSE),"") | I27: =IF(F27="","",I26+G27-H27)
... A215: =IF(Transaksi!J210="","",Transaksi!A210) | C215: =IFERROR(VLOOKUP(A215,Transaksi!$A$11:$C$1000,3,FALSE),"") | D215: =IFERROR(VLOOKUP(A215,Transaksi!$A$11:$D$1000,4,FALSE),"") | E215: =IFERROR(VLOOKUP(A215,Transaksi!$A$11:$E$1000,5,FALSE),"") | F215: =IFERROR(VLOOKUP(A215,Transaksi!$A$11:$F$1000,6,FALSE),"") | G215: =IFERROR(VLOOKUP(A215,Transaksi!$A$11:$G$1000,7,FALSE),"") | H215: =IFERROR(VLOOKUP(A215,Transaksi!$A$11:$H$1000,8,FALSE),"") | I215: =IF(F215="","",I214+G215-H215)
C216: =IFERROR(VLOOKUP(A216,Transaksi!$A$11:$C$1000,3,FALSE),"") | D216: =IFERROR(VLOOKUP(A216,Transaksi!$A$11:$D$1000,4,FALSE),"") | E216: =IFERROR(VLOOKUP(A216,Transaksi!$A$11:$E$1000,5,FALSE),"") | F216: =IFERROR(VLOOKUP(A216,Transaksi!$A$11:$F$1000,6,FALSE),"") | G216: =IFERROR(VLOOKUP(A216,Transaksi!$A$11:$G$1000,7,FALSE),"") | H216: =IFERROR(VLOOKUP(A216,Transaksi!$A$11:$H$1000,8,FALSE),"") | I216: =IF(F216="","",I215+G216-H216)
C217: =IFERROR(VLOOKUP(A217,Transaksi!$A$11:$C$1000,3,FALSE),"") | D217: =IFERROR(VLOOKUP(A217,Transaksi!$A$11:$D$1000,4,FALSE),"") | E217: =IFERROR(VLOOKUP(A217,Transaksi!$A$11:$E$1000,5,FALSE),"") | F217: =IFERROR(VLOOKUP(A217,Transaksi!$A$11:$F$1000,6,FALSE),"") | G217: =IFERROR(VLOOKUP(A217,Transaksi!$A$11:$G$1000,7,FALSE),"") | H217: =IFERROR(VLOOKUP(A217,Transaksi!$A$11:$H$1000,8,FALSE),"") | I217: =IF(F217="","",I216+G217-H217)
C218: =IFERROR(VLOOKUP(A218,Transaksi!$A$11:$C$1000,3,FALSE),"") | D218: =IFERROR(VLOOKUP(A218,Transaksi!$A$11:$D$1000,4,FALSE),"") | E218: =IFERROR(VLOOKUP(A218,Transaksi!$A$11:$E$1000,5,FALSE),"") | F218: =IFERROR(VLOOKUP(A218,Transaksi!$A$11:$F$1000,6,FALSE),"") | G218: =IFERROR(VLOOKUP(A218,Transaksi!$A$11:$G$1000,7,FALSE),"") | H218: =IFERROR(VLOOKUP(A218,Transaksi!$A$11:$H$1000,8,FALSE),"") | I218: =IF(F218="","",I217+G218-H218)
C219: =IFERROR(VLOOKUP(A219,Transaksi!$A$11:$C$1000,3,FALSE),"") | D219: =IFERROR(VLOOKUP(A219,Transaksi!$A$11:$D$1000,4,FALSE),"") | E219: =IFERROR(VLOOKUP(A219,Transaksi!$A$11:$E$1000,5,FALSE),"") | F219: =IFERROR(VLOOKUP(A219,Transaksi!$A$11:$F$1000,6,FALSE),"") | G219: =IFERROR(VLOOKUP(A219,Transaksi!$A$11:$G$1000,7,FALSE),"") | H219: =IFERROR(VLOOKUP(A219,Transaksi!$A$11:$H$1000,8,FALSE),"") | I219: =IF(F219="","",I218+G219-H219)
C220: =IFERROR(VLOOKUP(A220,Transaksi!$A$11:$C$1000,3,FALSE),"") | D220: =IFERROR(VLOOKUP(A220,Transaksi!$A$11:$D$1000,4,FALSE),"") | E220: =IFERROR(VLOOKUP(A220,Transaksi!$A$11:$E$1000,5,FALSE),"") | F220: =IFERROR(VLOOKUP(A220,Transaksi!$A$11:$F$1000,6,FALSE),"") | G220: =IFERROR(VLOOKUP(A220,Transaksi!$A$11:$G$1000,7,FALSE),"") | H220: =IFERROR(VLOOKUP(A220,Transaksi!$A$11:$H$1000,8,FALSE),"") | I220: =IF(F220="","",I219+G220-H220)
C221: =IFERROR(VLOOKUP(A221,Transaksi!$A$11:$C$1000,3,FALSE),"") | D221: =IFERROR(VLOOKUP(A221,Transaksi!$A$11:$D$1000,4,FALSE),"") | E221: =IFERROR(VLOOKUP(A221,Transaksi!$A$11:$E$1000,5,FALSE),"") | F221: =IFERROR(VLOOKUP(A221,Transaksi!$A$11:$F$1000,6,FALSE),"") | G221: =IFERROR(VLOOKUP(A221,Transaksi!$A$11:$G$1000,7,FALSE),"") | H221: =IFERROR(VLOOKUP(A221,Transaksi!$A$11:$H$1000,8,FALSE),"") | I221: =IF(F221="","",I220+G221-H221)
C222: =IFERROR(VLOOKUP(A222,Transaksi!$A$11:$C$1000,3,FALSE),"") | D222: =IFERROR(VLOOKUP(A222,Transaksi!$A$11:$D$1000,4,FALSE),"") | E222: =IFERROR(VLOOKUP(A222,Transaksi!$A$11:$E$1000,5,FALSE),"") | F222: =IFERROR(VLOOKUP(A222,Transaksi!$A$11:$F$1000,6,FALSE),"") | G222: =IFERROR(VLOOKUP(A222,Transaksi!$A$11:$G$1000,7,FALSE),"") | H222: =IFERROR(VLOOKUP(A222,Transaksi!$A$11:$H$1000,8,FALSE),"") | I222: =IF(F222="","",I221+G222-H222)
C223: =IFERROR(VLOOKUP(A223,Transaksi!$A$11:$C$1000,3,FALSE),"") | D223: =IFERROR(VLOOKUP(A223,Transaksi!$A$11:$D$1000,4,FALSE),"") | E223: =IFERROR(VLOOKUP(A223,Transaksi!$A$11:$E$1000,5,FALSE),"") | F223: =IFERROR(VLOOKUP(A223,Transaksi!$A$11:$F$1000,6,FALSE),"") | G223: =IFERROR(VLOOKUP(A223,Transaksi!$A$11:$G$1000,7,FALSE),"") | H223: =IFERROR(VLOOKUP(A223,Transaksi!$A$11:$H$1000,8,FALSE),"") | I223: =IF(F223="","",I222+G223-H223)
C224: =IFERROR(VLOOKUP(A224,Transaksi!$A$11:$C$1000,3,FALSE),"") | D224: =IFERROR(VLOOKUP(A224,Transaksi!$A$11:$D$1000,4,FALSE),"") | E224: =IFERROR(VLOOKUP(A224,Transaksi!$A$11:$E$1000,5,FALSE),"") | F224: =IFERROR(VLOOKUP(A224,Transaksi!$A$11:$F$1000,6,FALSE),"") | G224: =IFERROR(VLOOKUP(A224,Transaksi!$A$11:$G$1000,7,FALSE),"") | H224: =IFERROR(VLOOKUP(A224,Transaksi!$A$11:$H$1000,8,FALSE),"") | I224: =IF(F224="","",I223+G224-H224)
C225: =IFERROR(VLOOKUP(A225,Transaksi!$A$11:$C$1000,3,FALSE),"") | D225: =IFERROR(VLOOKUP(A225,Transaksi!$A$11:$D$1000,4,FALSE),"") | E225: =IFERROR(VLOOKUP(A225,Transaksi!$A$11:$E$1000,5,FALSE),"") | F225: =IFERROR(VLOOKUP(A225,Transaksi!$A$11:$F$1000,6,FALSE),"") | G225: =IFERROR(VLOOKUP(A225,Transaksi!$A$11:$G$1000,7,FALSE),"") | H225: =IFERROR(VLOOKUP(A225,Transaksi!$A$11:$H$1000,8,FALSE),"") | I225: =IF(F225="","",I224+G225-H225)
C226: =IFERROR(VLOOKUP(A226,Transaksi!$A$11:$C$1000,3,FALSE),"") | D226: =IFERROR(VLOOKUP(A226,Transaksi!$A$11:$D$1000,4,FALSE),"") | E226: =IFERROR(VLOOKUP(A226,Transaksi!$A$11:$E$1000,5,FALSE),"") | F226: =IFERROR(VLOOKUP(A226,Transaksi!$A$11:$F$1000,6,FALSE),"") | G226: =IFERROR(VLOOKUP(A226,Transaksi!$A$11:$G$1000,7,FALSE),"") | H226: =IFERROR(VLOOKUP(A226,Transaksi!$A$11:$H$1000,8,FALSE),"") | I226: =IF(F226="","",I225+G226-H226)
C227: =IFERROR(VLOOKUP(A227,Transaksi!$A$11:$C$1000,3,FALSE),"") | D227: =IFERROR(VLOOKUP(A227,Transaksi!$A$11:$D$1000,4,FALSE),"") | E227: =IFERROR(VLOOKUP(A227,Transaksi!$A$11:$E$1000,5,FALSE),"") | F227: =IFERROR(VLOOKUP(A227,Transaksi!$A$11:$F$1000,6,FALSE),"") | G227: =IFERROR(VLOOKUP(A227,Transaksi!$A$11:$G$1000,7,FALSE),"") | H227: =IFERROR(VLOOKUP(A227,Transaksi!$A$11:$H$1000,8,FALSE),"") | I227: =IF(F227="","",I226+G227-H227)
... C645: =IFERROR(VLOOKUP(A645,Transaksi!$A$11:$C$1000,3,FALSE),"") | D645: =IFERROR(VLOOKUP(A645,Transaksi!$A$11:$D$1000,4,FALSE),"") | E645: =IFERROR(VLOOKUP(A645,Transaksi!$A$11:$E$1000,5,FALSE),"") | F645: =IFERROR(VLOOKUP(A645,Transaksi!$A$11:$F$1000,6,FALSE),"") | G645: =IFERROR(VLOOKUP(A645,Transaksi!$A$11:$G$1000,7,FALSE),"") | H645: =IFERROR(VLOOKUP(A645,Transaksi!$A$11:$H$1000,8,FALSE),"") | I645: =IF(F645="","",I644+G645-H645)

Sheet BP Bank
C5: BUKU PEMBANTU KAS DI BANK
C6: =Transaksi!C5 -> Periode : 05-01-2026 s.d. 17-01-2026
C8: Nama SPPG | E8: =": "&Setup!C6 -> : Input Nama SPPG di sini
B9: Transaksi! | C9: ID SPPG | E9: =": "&Setup!C7 -> :
B10: J | C10: Alamat | E10: =": "&Setup!C8 -> : | H10: Saldo Awal | I10: =IF(F11="","",VLOOKUP(F11,'Saldo Buku'!C8:D28,2,FALSE)) -> 0
B11: W1000 | C11: Buku Pembantu Kas (dapat dipilih): | F11: Kas di Bank | H11: Saldo Akhir | I11: =I10+SUM(G16:G215)-SUM(H16:H215) -> 0
C13: Bulan | E13: No. Bukti | F13: Uraian Transaksi | G13: Debet | H13: Kredit | I13: Saldo
C14: 1 | E14: 2 | F14: 3 | G14: 4 | H14: 5 | I14: 6
A15: Row | B15: Next | C15: x | F15: SALDO AWAL BULAN BERJALAN | G15: =I10 -> 0 | H15: 0 | I15: =I10 -> 0
A16: =IFERROR(VLOOKUP(F11,Transaksi!J11:W1000,14,FALSE),"") | B16: =IF(A16="","",A16+1) | C16: =IFERROR(VLOOKUP(A16,Transaksi!$A$11:$C$1000,3,FALSE),"") | D16: =IFERROR(VLOOKUP(A16,Transaksi!$A$11:$D$1000,4,FALSE),"") | E16: =IFERROR(VLOOKUP(A16,Transaksi!$A$11:$E$1000,5,FALSE),"") | F16: =IFERROR(VLOOKUP(A16,Transaksi!$A$11:$F$1000,6,FALSE),"") | G16: =IFERROR(VLOOKUP(A16,Transaksi!$A$11:$G$1000,7,FALSE),"") | H16: =IFERROR(VLOOKUP(A16,Transaksi!$A$11:$H$1000,8,FALSE),"") | I16: =IF(F16="","",I15+G16-H16)
